2023-11-02 13:21:52,442 - app - ERROR - Exception on /questions [GET]
Traceback (most recent call last):
  File "C:\Users\NC\AppData\Local\Programs\Python\Python311\Lib\site-packages\sqlalchemy\engine\base.py", line 1965, in _exec_single_context
    self.dialect.do_execute(
  File "C:\Users\NC\AppData\Local\Programs\Python\Python311\Lib\site-packages\sqlalchemy\engine\default.py", line 921, in do_execute
    cursor.execute(statement, parameters)
psycopg2.OperationalError: SSL connection has been closed unexpectedly


The above exception was the direct cause of the following exception:

Traceback (most recent call last):
  File "C:\Users\NC\AppData\Local\Programs\Python\Python311\Lib\site-packages\flask\app.py", line 2529, in wsgi_app
    response = self.full_dispatch_request()
               ^^^^^^^^^^^^^^^^^^^^^^^^^^^^
  File "C:\Users\NC\AppData\Local\Programs\Python\Python311\Lib\site-packages\flask\app.py", line 1825, in full_dispatch_request
    rv = self.handle_user_exception(e)
         ^^^^^^^^^^^^^^^^^^^^^^^^^^^^^
  File "C:\Users\NC\AppData\Local\Programs\Python\Python311\Lib\site-packages\flask_cors\extension.py", line 176, in wrapped_function
    return cors_after_request(app.make_response(f(*args, **kwargs)))
                                                ^^^^^^^^^^^^^^^^^^
  File "C:\Users\NC\AppData\Local\Programs\Python\Python311\Lib\site-packages\flask\app.py", line 1823, in full_dispatch_request
    rv = self.dispatch_request()
         ^^^^^^^^^^^^^^^^^^^^^^^
  File "C:\Users\NC\AppData\Local\Programs\Python\Python311\Lib\site-packages\flask\app.py", line 1799, in dispatch_request
    return self.ensure_sync(self.view_functions[rule.endpoint])(**view_args)
           ^^^^^^^^^^^^^^^^^^^^^^^^^^^^^^^^^^^^^^^^^^^^^^^^^^^^^^^^^^^^^^^^^
  File "C:\Users\NC\Desktop\Full Stack Web Developer\CapStone\app.py", line 44, in get_questions
    selection = Question.query.order_by(Question.id).all()
                ^^^^^^^^^^^^^^^^^^^^^^^^^^^^^^^^^^^^^^^^^^
  File "C:\Users\NC\AppData\Local\Programs\Python\Python311\Lib\site-packages\sqlalchemy\orm\query.py", line 2688, in all
    return self._iter().all()  # type: ignore
           ^^^^^^^^^^^^
  File "C:\Users\NC\AppData\Local\Programs\Python\Python311\Lib\site-packages\sqlalchemy\orm\query.py", line 2842, in _iter
    result: Union[ScalarResult[_T], Result[_T]] = self.session.execute(
                                                  ^^^^^^^^^^^^^^^^^^^^^
  File "C:\Users\NC\AppData\Local\Programs\Python\Python311\Lib\site-packages\sqlalchemy\orm\session.py", line 2262, in execute
    return self._execute_internal(
           ^^^^^^^^^^^^^^^^^^^^^^^
  File "C:\Users\NC\AppData\Local\Programs\Python\Python311\Lib\site-packages\sqlalchemy\orm\session.py", line 2144, in _execute_internal
    result: Result[Any] = compile_state_cls.orm_execute_statement(
                          ^^^^^^^^^^^^^^^^^^^^^^^^^^^^^^^^^^^^^^^^
  File "C:\Users\NC\AppData\Local\Programs\Python\Python311\Lib\site-packages\sqlalchemy\orm\context.py", line 293, in orm_execute_statement
    result = conn.execute(
             ^^^^^^^^^^^^^
  File "C:\Users\NC\AppData\Local\Programs\Python\Python311\Lib\site-packages\sqlalchemy\engine\base.py", line 1412, in execute
    return meth(
           ^^^^^
  File "C:\Users\NC\AppData\Local\Programs\Python\Python311\Lib\site-packages\sqlalchemy\sql\elements.py", line 515, in _execute_on_connection
    return connection._execute_clauseelement(
           ^^^^^^^^^^^^^^^^^^^^^^^^^^^^^^^^^^
  File "C:\Users\NC\AppData\Local\Programs\Python\Python311\Lib\site-packages\sqlalchemy\engine\base.py", line 1635, in _execute_clauseelement
    ret = self._execute_context(
          ^^^^^^^^^^^^^^^^^^^^^^
  File "C:\Users\NC\AppData\Local\Programs\Python\Python311\Lib\site-packages\sqlalchemy\engine\base.py", line 1844, in _execute_context
    return self._exec_single_context(
           ^^^^^^^^^^^^^^^^^^^^^^^^^^
  File "C:\Users\NC\AppData\Local\Programs\Python\Python311\Lib\site-packages\sqlalchemy\engine\base.py", line 1984, in _exec_single_context
    self._handle_dbapi_exception(
  File "C:\Users\NC\AppData\Local\Programs\Python\Python311\Lib\site-packages\sqlalchemy\engine\base.py", line 2339, in _handle_dbapi_exception
    raise sqlalchemy_exception.with_traceback(exc_info[2]) from e
  File "C:\Users\NC\AppData\Local\Programs\Python\Python311\Lib\site-packages\sqlalchemy\engine\base.py", line 1965, in _exec_single_context
    self.dialect.do_execute(
  File "C:\Users\NC\AppData\Local\Programs\Python\Python311\Lib\site-packages\sqlalchemy\engine\default.py", line 921, in do_execute
    cursor.execute(statement, parameters)
sqlalchemy.exc.OperationalError: (psycopg2.OperationalError) SSL connection has been closed unexpectedly

[SQL: SELECT questions.id AS questions_id, questions.question AS questions_question, questions.answer AS questions_answer, questions.category AS questions_category, questions.difficulty AS questions_difficulty 
FROM questions ORDER BY questions.id]
(Background on this error at: https://sqlalche.me/e/20/e3q8)
